//This code snippet creates a custom Exception class and handles it within a try-catch block.

//Definition of custom Exception class
class NegativeNumberException(message: String) : Exception(message)

//Function to calculate the square root of a number
fun sqrt(num: Double): Double {
    //Check if the number is negative
    if (num < 0.0) {
        //Throw custom Exception with a message
        throw NegativeNumberException("Number must be positive")
    }
    //Calculate the square root of the number
    return Math.sqrt(num)
}

fun main() {
    //Try block to handle potential Exceptions
    try {
        val num = -4.0
        //Call the sqrt function and store the result in a variable
        val result = sqrt(num)
        //Print the result
        println("Square root of $num is $result")
    } catch (e: NegativeNumberException) {
        //Print the custom Exception message
        println(e.message)
    }
}