// Example code using exceptions in D Programming Language

import std.stdio;

void divide(int x, int y) // Function to divide two integers
{
  // Try block to catch any possible exceptions
  try
  {
    // If y is equal to 0, throw an exception
    if(y == 0) 
    {
      throw new Exception("Cannot divide by zero"); 
    }

    // Otherwise, print the result of x / y
    writeln("Result: ", x/y); 
  }
  // Catch block to handle the thrown exception
  catch(Exception e)
  {
    // Print the error message from the caught exception
    writeln(e.msg);
  }
}

void main()
{
  // Call the divide function with different values
  divide(10, 2); // Output: Result: 5
  divide(8, 0); // Output: Cannot divide by zero
}